import { CustomError, UserNotFoud } from "../error/customError";
import { EditUserInput, User } from "../model/user";
import { BaseDatabase } from "./BaseDatabase";

export class UserDatabase extends BaseDatabase {
  public insertUser = async (user: User):Promise<void> => {
    try {
      await UserDatabase.connection
        .insert({
          id: user.id,
          email: user.email,
          password: user.password,
        })
        .into("Auth_users");
    } catch (error: any) {
      throw new CustomError(400, error.message);
    }
  };

  public editUser = async (user: EditUserInput):Promise<void> => {
    try {
      await UserDatabase.connection
        .update({ name: user.name, nickname: user.nickname })
        .where({ id: user.id })
        .into("Auth_users");
    } catch (error: any) {
      throw new CustomError(400, error.message);
    }
  };

  public findUserByEmail = async (email: string):Promise<User> => {
    try {
      const result = await UserDatabase.connection("Auth_users").where({email})
      
      if(!result.length) {
        throw new UserNotFoud()
      }

     return result[0]
    } catch (error: any) {
      throw new CustomError(400, error.message);
    }
  };

}
